Workbook

Sheet Raw data
A1: Sector | B1: Year | C1: Month | D1: Cereals and products | E1: Meat and fish | F1: Egg | G1: Milk and products | H1: Oils and fats | I1: Fruits | J1: Vegetables | K1: Pulses and products | L1: Sugar and Confectionery | M1: Spices | N1: Non-alcoholic beverages | O1: Prepared meals, scks, sweets etc. | P1: Food and beverages | Q1: Pan, tobacco and intoxicants | R1: Clothing | S1: Footwear | T1: Clothing and footwear | U1: Housing | V1: Fuel and light | W1: Household goods and services | X1: Health | Y1: Transport and communication | Z1: Recreation and amusement | AA1: Education | AB1: Persol care and effects | AC1: Miscellaneous | AD1: General index | AF1: Cereals and products | AG1: Meat and fish | AH1: Egg | AI1: Milk and products | AJ1: Oils and fats | AK1: Fruits | AL1: Vegetables | AM1: Pulses and products | AN1: Sugar and Confectionery | AO1: Spices | AP1: Non-alcoholic beverages | AQ1: Prepared meals, scks, sweets etc. | AR1: Food and beverages | AS1: Pan, tobacco and intoxicants | AT1: Clothing | AU1: Footwear | AV1: Clothing and footwear | AW1: Housing | AX1: Fuel and light | AY1: Household goods and services | AZ1: Health | BA1: Transport and communication | BB1: Recreation and amusement | BC1: Education | BD1: Persol care and effects | BE1: Miscellaneous | BF1: General index
A2: Rural | B2: 2013 | C2: January | D2: 107.5 | E2: 106.3 | F2: 108.1 | G2: 104.9 | H2: 106.1 | I2: 103.9 | J2: 101.9 | K2: 106.1 | L2: 106.8 | M2: 103.1 | N2: 104.8 | O2: 106.7 | P2: 105.5 | Q2: 105.1 | R2: 106.5 | S2: 105.8 | T2: 106.4 | V2: 105.5 | W2: 104.8 | X2: 104 | Y2: 103.3 | Z2: 103.4 | AA2: 103.8 | AB2: 104.7 | AC2: 104 | AD2: 105.1
A3: Urban | B3: 2013 | C3: January | D3: 110.5 | E3: 109.1 | F3: 113 | G3: 103.6 | H3: 103.4 | I3: 102.3 | J3: 102.9 | K3: 105.8 | L3: 105.1 | M3: 101.8 | N3: 105.1 | O3: 107.9 | P3: 105.9 | Q3: 105.2 | R3: 105.9 | S3: 105 | T3: 105.8 | U3: 100.3 | V3: 105.4 | W3: 104.8 | X3: 104.1 | Y3: 103.2 | Z3: 102.9 | AA3: 103.5 | AB3: 104.3 | AC3: 103.7 | AD3: 104 | AF3: Moving average used here: IF(D2<>"",D2,ROUND(AVERAGE(D2:D8),1))
A4: Rural+Urban | B4: 2013 | C4: January | D4: 108.4 | E4: 107.3 | F4: 110 | G4: 104.4 | H4: 105.1 | I4: 103.2 | J4: 102.2 | K4: 106 | L4: 106.2 | M4: 102.7 | N4: 104.9 | O4: 107.3 | P4: 105.6 | Q4: 105.1 | R4: 106.3 | S4: 105.5 | T4: 106.2 | U4: 100.3 | V4: 105.5 | W4: 104.8 | X4: 104 | Y4: 103.2 | Z4: 103.1 | AA4: 103.6 | AB4: 104.5 | AC4: 103.9 | AD4: 104.6
A5: Rural | B5: 2013 | C5: February | D5: 109.2 | E5: 108.7 | F5: 110.2 | G5: 105.4 | H5: 106.7 | I5: 104 | J5: 102.4 | K5: 105.9 | L5: 105.7 | M5: 103.1 | N5: 105.1 | O5: 107.7 | P5: 106.3 | Q5: 105.6 | R5: 107.1 | S5: 106.3 | T5: 107 | V5: 106.2 | W5: 105.2 | X5: 104.4 | Y5: 103.9 | Z5: 104 | AA5: 104.1 | AB5: 104.6 | AC5: 104.4 | AD5: 105.8
A6: Urban | B6: 2013 | C6: February | D6: 112.9 | E6: 112.9 | F6: 116.9 | G6: 104 | H6: 103.5 | I6: 103.1 | J6: 104.9 | K6: 104.1 | L6: 103.8 | M6: 102.3 | N6: 106 | O6: 109 | P6: 107.2 | Q6: 106 | R6: 106.6 | S6: 105.5 | T6: 106.4 | U6: 100.4 | V6: 105.7 | W6: 105.2 | X6: 104.7 | Y6: 104.4 | Z6: 103.3 | AA6: 103.7 | AB6: 104.3 | AC6: 104.3 | AD6: 104.7
A7: Rural+Urban | B7: 2013 | C7: February | D7: 110.4 | E7: 110.2 | F7: 112.8 | G7: 104.9 | H7: 105.5 | I7: 103.6 | J7: 103.2 | K7: 105.3 | L7: 105.1 | M7: 102.8 | N7: 105.5 | O7: 108.3 | P7: 106.6 | Q7: 105.7 | R7: 106.9 | S7: 106 | T7: 106.8 | U7: 100.4 | V7: 106 | W7: 105.2 | X7: 104.5 | Y7: 104.2 | Z7: 103.6 | AA7: 103.9 | AB7: 104.5 | AC7: 104.4 | AD7: 105.3
A8: Rural | B8: 2013 | C8: March | D8: 110.2 | E8: 108.8 | F8: 109.9 | G8: 105.6 | H8: 106.2 | I8: 105.7 | J8: 101.4 | K8: 105.7 | L8: 105 | M8: 103.3 | N8: 105.6 | O8: 108.2 | P8: 106.6 | Q8: 106.5 | R8: 107.6 | S8: 106.8 | T8: 107.5 | V8: 106.1 | W8: 105.6 | X8: 104.7 | Y8: 104.6 | Z8: 104 | AA8: 104.3 | AB8: 104.3 | AC8: 104.6 | AD8: 106
A9: Urban | B9: 2013 | C9: March | D9: 113.9 | E9: 111.4 | F9: 113.2 | G9: 104.3 | H9: 102.7 | I9: 104.9 | J9: 103.8 | K9: 103.5 | L9: 102.6 | M9: 102.4 | N9: 107 | O9: 109.8 | P9: 107.3 | Q9: 106.8 | R9: 107.2 | S9: 106 | T9: 107 | U9: 100.4 | V9: 106 | W9: 105.7 | X9: 105.2 | Y9: 105.5 | Z9: 103.5 | AA9: 103.8 | AB9: 104.2 | AC9: 104.9 | AD9: 105
A10: Rural+Urban | B10: 2013 | C10: March | D10: 111.4 | E10: 109.7 | F10: 111.2 | G10: 105.1 | H10: 104.9 | I10: 105.3 | J10: 102.2 | K10: 105 | L10: 104.2 | M10: 103 | N10: 106.2 | O10: 108.9 | P10: 106.9 | Q10: 106.6 | R10: 107.4 | S10: 106.5 | T10: 107.3 | U10: 100.4 | V10: 106.1 | W10: 105.6 | X10: 104.9 | Y10: 105.1 | Z10: 103.7 | AA10: 104 | AB10: 104.3 | AC10: 104.7 | AD10: 105.5
A11: Rural | B11: 2013 | C11: April | D11: 110.2 | E11: 109.5 | F11: 106.9 | G11: 106.3 | H11: 105.7 | I11: 108.3 | J11: 103.4 | K11: 105.7 | L11: 104.2 | M11: 103.2 | N11: 106.5 | O11: 108.8 | P11: 107.1 | Q11: 107.1 | R11: 108.1 | S11: 107.4 | T11: 108 | V11: 106.5 | W11: 106.1 | X11: 105.1 | Y11: 104.4 | Z11: 104.5 | AA11: 104.8 | AB11: 102.7 | AC11: 104.6 | AD11: 106.4
A12: Urban | B12: 2013 | C12: April | D12: 114.6 | E12: 113.4 | F12: 106 | G12: 104.7 | H12: 102.1 | I12: 109.5 | J12: 109.7 | K12: 104.6 | L12: 102 | M12: 103.5 | N12: 108.2 | O12: 110.6 | P12: 108.8 | Q12: 108.5 | R12: 107.9 | S12: 106.4 | T12: 107.7 | U12: 100.5 | V12: 106.4 | W12: 106.5 | X12: 105.7 | Y12: 105 | Z12: 104 | AA12: 105.2 | AB12: 103.2 | AC12: 105.1 | AD12: 105.7
A13: Rural+Urban | B13: 2013 | C13: April | D13: 111.6 | E13: 110.9 | F13: 106.6 | G13: 105.7 | H13: 104.4 | I13: 108.9 | J13: 105.5 | K13: 105.3 | L13: 103.5 | M13: 103.3 | N13: 107.2 | O13: 109.6 | P13: 107.7 | Q13: 107.5 | R13: 108 | S13: 107 | T13: 107.9 | U13: 100.5 | V13: 106.5 | W13: 106.3 | X13: 105.3 | Y13: 104.7 | Z13: 104.2 | AA13: 105 | AB13: 102.9 | AC13: 104.8 | AD13: 106.1
A14: Rural | B14: 2013 | C14: May | D14: 110.9 | E14: 109.8 | F14: 105.9 | G14: 107.5 | H14: 105.3 | I14: 108.1 | J14: 107.3 | K14: 106.1 | L14: 103.7 | M14: 104 | N14: 107.4 | O14: 109.9 | P14: 108.1 | Q14: 108.1 | R14: 108.8 | S14: 107.9 | T14: 108.6 | V14: 107.5 | W14: 106.8 | X14: 105.7 | Y14: 104.1 | Z14: 105 | AA14: 105.5 | AB14: 102.1 | AC14: 104.8 | AD14: 107.2
A15: Urban | B15: 2013 | C15: May | D15: 115.4 | E15: 114.2 | F15: 102.7 | G15: 105.5 | H15: 101.5 | I15: 110.6 | J15: 123.7 | K15: 105.2 | L15: 101.9 | M15: 105 | N15: 109.1 | O15: 111.3 | P15: 111.1 | Q15: 109.8 | R15: 108.5 | S15: 106.7 | T15: 108.3 | U15: 100.5 | V15: 107.2 | W15: 107.1 | X15: 106.2 | Y15: 103.9 | Z15: 104.6 | AA15: 105.7 | AB15: 102.6 | AC15: 104.9 | AD15: 106.6
A16: Rural+Urban | B16: 2013 | C16: May | D16: 112.3 | E16: 111.3 | F16: 104.7 | G16: 106.8 | H16: 103.9 | I16: 109.3 | J16: 112.9 | K16: 105.8 | L16: 103.1 | M16: 104.3 | N16: 108.1 | O16: 110.5 | P16: 109.2 | Q16: 108.6 | R16: 108.7 | S16: 107.4 | T16: 108.5 | U16: 100.5 | V16: 107.4 | W16: 106.9 | X16: 105.9 | Y16: 104 | Z16: 104.8 | AA16: 105.6 | AB16: 102.3 | AC16: 104.8 | AD16: 106.9
A17: Rural | B17: 2013 | C17: June | D17: 112.3 | E17: 112.1 | F17: 108.1 | G17: 108.3 | H17: 105.9 | I17: 109.2 | J17: 118 | K17: 106.8 | L17: 104.1 | M17: 105.4 | N17: 108.2 | O17: 111 | P17: 110.6 | Q17: 109 | R17: 109.7 | S17: 108.8 | T17: 109.5 | V17: 108.5 | W17: 107.5 | X17: 106.3 | Y17: 105 | Z17: 105.6 | AA17: 106.5 | AB17: 102.5 | AC17: 105.5 | AD17: 108.9
A18: Urban | B18: 2013 | C18: June | D18: 117 | E18: 120.1 | F18: 112.5 | G18: 107.3 | H18: 101.3 | I18: 112.4 | J18: 143.6 | K18: 105.4 | L18: 101.4 | M18: 106.4 | N18: 110 | O18: 112.2 | P18: 115 | Q18: 110.9 | R18: 109.2 | S18: 107.2 | T18: 108.9 | U18: 106.6 | V18: 108 | W18: 107.7 | X18: 106.5 | Y18: 105.2 | Z18: 105.2 | AA18: 108.1 | AB18: 103.3 | AC18: 106.1 | AD18: 109.7
A19: Rural+Urban | B19: 2013 | C19: June | D19: 113.8 | E19: 114.9 | F19: 109.8 | G19: 107.9 | H19: 104.2 | I19: 110.7 | J19: 126.7 | K19: 106.3 | L19: 103.2 | M19: 105.7 | N19: 109 | O19: 111.6 | P19: 112.2 | Q19: 109.5 | R19: 109.5 | S19: 108.1 | T19: 109.3 | U19: 106.6 | V19: 108.3 | W19: 107.6 | X19: 106.4 | Y19: 105.1 | Z19: 105.4 | AA19: 107.4 | AB19: 102.8 | AC19: 105.8 | AD19: 109.3
A20: Rural | B20: 2013 | C20: July | D20: 113.4 | E20: 114.9 | F20: 110.5 | G20: 109.3 | H20: 106.2 | I20: 110.3 | J20: 129.2 | K20: 107.1 | L20: 104.3 | M20: 106.4 | N20: 109.1 | O20: 112.1 | P20: 113.1 | Q20: 109.8 | R20: 110.5 | S20: 109.5 | T20: 110.3 | V20: 109.5 | W20: 108.3 | X20: 106.9 | Y20: 106.8 | Z20: 106.4 | AA20: 107.8 | AB20: 102.5 | AC20: 106.5 | AD20: 110.7
A21: Urban | B21: 2013 | C21: July | D21: 117.8 | E21: 119.2 | F21: 114 | G21: 108.3 | H21: 101.1 | I21: 113.2 | J21: 160.9 | K21: 105.1 | L21: 101.3 | M21: 107.5 | N21: 110.4 | O21: 113.1 | P21: 117.5 | Q21: 111.7 | R21: 109.8 | S21: 107.8 | T21: 109.5 | U21: 107.7 | V21: 108.6 | W21: 108.1 | X21: 107.1 | Y21: 107.3 | Z21: 105.9 | AA21: 110.1 | AB21: 103.2 | AC21: 107.3 | AD21: 111.4
A22: Rural+Urban | B22: 2013 | C22: July | D22: 114.8 | E22: 116.4 | F22: 111.9 | G22: 108.9 | H22: 104.3 | I22: 111.7 | J22: 140 | K22: 106.4 | L22: 103.3 | M22: 106.8 | N22: 109.6 | O22: 112.6 | P22: 114.7 | Q22: 110.3 | R22: 110.2 | S22: 108.8 | T22: 110 | U22: 107.7 | V22: 109.2 | W22: 108.2 | X22: 107 | Y22: 107.1 | Z22: 106.1 | AA22: 109.1 | AB22: 102.8 | AC22: 106.9 | AD22: 111
A23: Rural | B23: 2013 | C23: August | D23: 114.3 | E23: 115.4 | F23: 111.1 | G23: 110 | H23: 106.4 | I23: 110.8 | J23: 138.9 | K23: 107.4 | L23: 104.1 | M23: 106.9 | N23: 109.7 | O23: 112.6 | P23: 114.9 | Q23: 110.7 | R23: 111.3 | S23: 110.2 | T23: 111.1 | V23: 109.9 | W23: 108.7 | X23: 107.5 | Y23: 107.8 | Z23: 106.8 | AA23: 108.7 | AB23: 105 | AC23: 107.5 | AD23: 112.1
A24: Urban | B24: 2013 | C24: August | D24: 118.3 | E24: 120.4 | F24: 112.7 | G24: 108.9 | H24: 101.1 | I24: 108.7 | J24: 177 | K24: 104.7 | L24: 101 | M24: 108.5 | N24: 110.9 | O24: 114.3 | P24: 119.6 | Q24: 112.4 | R24: 110.6 | S24: 108.3 | T24: 110.2 | U24: 108.9 | V24: 109.3 | W24: 108.7 | X24: 107.6 | Y24: 108.1 | Z24: 106.5 | AA24: 110.8 | AB24: 106 | AC24: 108.3 | AD24: 112.7
A25: Rural+Urban | B25: 2013 | C25: August | D25: 115.6 | E25: 117.2 | F25: 111.7 | G25: 109.6 | H25: 104.5 | I25: 109.8 | J25: 151.8 | K25: 106.5 | L25: 103.1 | M25: 107.4 | N25: 110.2 | O25: 113.4 | P25: 116.6 | Q25: 111.2 | R25: 111 | S25: 109.4 | T25: 110.7 | U25: 108.9 | V25: 109.7 | W25: 108.7 | X25: 107.5 | Y25: 108 | Z25: 106.6 | AA25: 109.9 | AB25: 105.4 | AC25: 107.9 | AD25: 112.4
A26: Rural | B26: 2013 | C26: September | D26: 115.4 | E26: 115.7 | F26: 111.7 | G26: 111 | H26: 107.4 | I26: 110.9 | J26: 154 | K26: 108.1 | L26: 104.2 | M26: 107.9 | N26: 110.4 | O26: 114 | P26: 117.8 | Q26: 111.7 | R26: 112.7 | S26: 111.4 | T26: 112.5 | V26: 111.1 | W26: 109.6 | X26: 108.3 | Y26: 109.3 | Z26: 107.7 | AA26: 109.8 | AB26: 106.7 | AC26: 108.7 | AD26: 114.2
A27: Urban | B27: 2013 | C27: September | D27: 118.6 | E27: 119.1 | F27: 113.2 | G27: 109.6 | H27: 101.7 | I27: 103.2 | J27: 174.3 | K27: 105.1 | L27: 100.8 | M27: 109.1 | N27: 111.1 | O27: 115.4 | P27: 119.2 | Q27: 112.9 | R27: 111.4 | S27: 109 | T27: 111.1 | U27: 109.7 | V27: 109.5 | W27: 109.6 | X27: 107.9 | Y27: 110.4 | Z27: 107.4 | AA27: 111.2 | AB27: 106.9 | AC27: 109.4 | AD27: 113.2
A28: Rural+Urban | B28: 2013 | C28: September | D28: 116.4 | E28: 116.9 | F28: 112.3 | G28: 110.5 | H28: 105.3 | I28: 107.3 | J28: 160.9 | K28: 107.1 | L28: 103.1 | M28: 108.3 | N28: 110.7 | O28: 114.6 | P28: 118.3 | Q28: 112 | R28: 112.2 | S28: 110.4 | T28: 111.9 | U28: 109.7 | V28: 110.5 | W28: 109.6 | X28: 108.1 | Y28: 109.9 | Z28: 107.5 | AA28: 110.6 | AB28: 106.8 | AC28: 109 | AD28: 113.7
A29: Rural | B29: 2013 | C29: October | D29: 116.3 | E29: 115.4 | F29: 112.6 | G29: 111.7 | H29: 107.7 | I29: 113.2 | J29: 164.9 | K29: 108.3 | L29: 103.9 | M29: 108.2 | N29: 111.1 | O29: 114.9 | P29: 119.8 | Q29: 112.2 | R29: 113.6 | S29: 112.3 | T29: 113.4 | V29: 111.6 | W29: 110.4 | X29: 108.9 | Y29: 109.3 | Z29: 108.3 | AA29: 110.2 | AB29: 107.5 | AC29: 109.1 | AD29: 115.5
A30: Urban | B30: 2013 | C30: October | D30: 118.9 | E30: 118.1 | F30: 114.5 | G30: 110.4 | H30: 102.3 | I30: 106.2 | J30: 183.5 | K30: 105.3 | L30: 100.2 | M30: 109.6 | N30: 111.4 | O30: 116 | P30: 120.8 | Q30: 113.5 | R30: 112.5 | S30: 109.7 | T30: 112 | U30: 110.5 | V30: 109.7 | W30: 110.2 | X30: 108.2 | Y30: 109.7 | Z30: 108 | AA30: 111.3 | AB30: 107.3 | AC30: 109.4 | AD30: 114
A31: Rural+Urban | B31: 2013 | C31: October | D31: 117.1 | E31: 116.3 | F31: 113.3 | G31: 111.2 | H31: 105.7 | I31: 109.9 | J31: 171.2 | K31: 107.3 | L31: 102.7 | M31: 108.7 | N31: 111.2 | O31: 115.4 | P31: 120.2 | Q31: 112.5 | R31: 113.2 | S31: 111.2 | T31: 112.8 | U31: 110.5 | V31: 110.9 | W31: 110.3 | X31: 108.6 | Y31: 109.5 | Z31: 108.1 | AA31: 110.8 | AB31: 107.4 | AC31: 109.2 | AD31: 114.8
A32: Rural | B32: 2013 | C32: November | D32: 117.3 | E32: 114.9 | F32: 116.2 | G32: 112.8 | H32: 108.9 | I32: 116.6 | J32: 178.1 | K32: 109.1 | L32: 103.6 | M32: 109 | N32: 111.8 | O32: 116 | P32: 122.5 | Q32: 112.8 | R32: 114.6 | S32: 113.1 | T32: 114.4 | V32: 112.6 | W32: 111.3 | X32: 109.7 | Y32: 109.6 | Z32: 108.7 | AA32: 111 | AB32: 108.2 | AC32: 109.8 | AD32: 117.4
A33: Urban | B33: 2013 | C33: November | D33: 119.8 | E33: 116.3 | F33: 122.6 | G33: 112 | H33: 103.2 | I33: 110 | J33: 192.8 | K33: 106.3 | L33: 99.5 | M33: 110.3 | N33: 111.8 | O33: 117.1 | P33: 122.9 | Q33: 114.1 | R33: 113.5 | S33: 110.3 | T33: 113 | U33: 111.1 | V33: 110 | W33: 110.9 | X33: 108.6 | Y33: 109.5 | Z33: 108.5 | AA33: 111.3 | AB33: 107.9 | AC33: 109.6 | AD33: 115
A34: Rural+Urban | B34: 2013 | C34: November | D34: 118.1 | E34: 115.4 | F34: 118.7 | G34: 112.5 | H34: 106.8 | I34: 113.5 | J34: 183.1 | K34: 108.2 | L34: 102.2 | M34: 109.4 | N34: 111.8 | O34: 116.5 | P34: 122.6 | Q34: 113.1 | R34: 114.2 | S34: 111.9 | T34: 113.8 | U34: 111.1 | V34: 111.6 | W34: 111.1 | X34: 109.3 | Y34: 109.5 | Z34: 108.6 | AA34: 111.2 | AB34: 108.1 | AC34: 109.7 | AD34: 116.3
A35: Rural | B35: 2013 | C35: December | D35: 118.4 | E35: 115.9 | F35: 120.4 | G35: 113.8 | H35: 109.5 | I35: 115.5 | J35: 145.7 | K35: 109.5 | L35: 102.9 | M35: 109.8 | N35: 112.1 | O35: 116.8 | P35: 118.7 | Q35: 113.6 | R35: 115.8 | S35: 114 | T35: 115.5 | V35: 112.8 | W35: 112.1 | X35: 110.1 | Y35: 109.9 | Z35: 109.2 | AA35: 111.6 | AB35: 108.1 | AC35: 110.1 | AD35: 115.5
A36: Urban | B36: 2013 | C36: December | D36: 120.5 | E36: 118.1 | F36: 128.5 | G36: 112.8 | H36: 103.4 | I36: 110.7 | J36: 144.8 | K36: 107.1 | L36: 98.6 | M36: 111.9 | N36: 112.1 | O36: 118.1 | P36: 117.8 | Q36: 115 | R36: 114.2 | S36: 110.9 | T36: 113.7 | U36: 110.7 | V36: 110.4 | W36: 111.3 | X36: 109 | Y36: 109.7 | Z36: 108.9 | AA36: 111.4 | AB36: 107.7 | AC36: 109.8 | AD36: 113.3
A37: Rural+Urban | B37: 2013 | C37: December | D37: 119.1 | E37: 116.7 | F37: 123.5 | G37: 113.4 | H37: 107.3 | I37: 113.3 | J37: 145.4 | K37: 108.7 | L37: 101.5 | M37: 110.5 | N37: 112.1 | O37: 117.4 | P37: 118.4 | Q37: 114 | R37: 115.2 | S37: 112.7 | T37: 114.8 | U37: 110.7 | V37: 111.9 | W37: 111.7 | X37: 109.7 | Y37: 109.8 | Z37: 109 | AA37: 111.5 | AB37: 107.9 | AC37: 110 | AD37: 114.5
A38: Rural | B38: 2014 | C38: January | D38: 118.9 | E38: 117.1 | F38: 120.5 | G38: 114.4 | H38: 109 | I38: 115.5 | J38: 123.9 | K38: 109.6 | L38: 101.8 | M38: 110.2 | N38: 112.4 | O38: 117.3 | P38: 116 | Q38: 114 | R38: 116.5 | S38: 114.5 | T38: 116.2 | V38: 113 | W38: 112.6 | X38: 110.6 | Y38: 110.5 | Z38: 109.6 | AA38: 111.8 | AB38: 108.3 | AC38: 110.6 | AD38: 114.2
A39: Urban | B39: 2014 | C39: January | D39: 121.2 | E39: 122 | F39: 129.9 | G39: 113.6 | H39: 102.9 | I39: 112.1 | J39: 118.9 | K39: 107.5 | L39: 96.9 | M39: 112.7 | N39: 112.1 | O39: 119 | P39: 115.5 | Q39: 115.7 | R39: 114.8 | S39: 111.3 | T39: 114.3 | U39: 111.6 | V39: 111 | W39: 111.9 | X39: 109.7 | Y39: 110.8 | Z39: 109.8 | AA39: 111.5 | AB39: 108 | AC39: 110.5 | AD39: 112.9
A40: Rural+Urban | B40: 2014 | C40: January | D40: 119.6 | E40: 118.8 | F40: 124.1 | G40: 114.1 | H40: 106.8 | I40: 113.9 | J40: 122.2 | K40: 108.9 | L40: 100.2 | M40: 111 | N40: 112.3 | O40: 118.1 | P40: 115.8 | Q40: 114.5 | R40: 115.8 | S40: 113.2 | T40: 115.4 | U40: 111.6 | V40: 112.2 | W40: 112.3 | X40: 110.3 | Y40: 110.7 | Z40: 109.7 | AA40: 111.6 | AB40: 108.2 | AC40: 110.6 | AD40: 113.6
...

Sheet Working sheet
A1: Sector | B1: Year | C1: Month | D1: Cereals and products | E1: Meat and fish | F1: Egg | G1: Milk and products | H1: Oils and fats | I1: Fruits | J1: Vegetables | K1: Pulses and products | L1: Sugar and Confectionery | M1: Spices | N1: Non-alcoholic beverages | O1: Prepared meals, scks, sweets etc. | P1: Food and beverages | Q1: Pan, tobacco and intoxicants | R1: Clothing | S1: Footwear | T1: Clothing and footwear | U1: Housing | V1: Fuel and light | W1: Household goods and services | X1: Health | Y1: Transport and communication | Z1: Recreation and amusement | AA1: Education | AB1: Persol care and effects | AC1: Miscellaneous | AD1: General index | AF1: Food & Beverages | AG1: Pan, Tobacco & Intoxicants | AH1: Clothing & Footwear | AI1: Housing | AJ1: Fuel & Light | AK1: Miscellaneous
A2: Rural | B2: 2013 | C2: January | D2: 107.5 | E2: 106.3 | F2: 108.1 | G2: 104.9 | H2: 106.1 | I2: 103.9 | J2: 101.9 | K2: 106.1 | L2: 106.8 | M2: 103.1 | N2: 104.8 | O2: 106.7 | P2: 105.5 | Q2: 105.1 | R2: 106.5 | S2: 105.8 | T2: 106.4 | U2: 100.4 | V2: 105.5 | W2: 104.8 | X2: 104 | Y2: 103.3 | Z2: 103.4 | AA2: 103.8 | AB2: 104.7 | AC2: 104 | AD2: 105.1 | AF2: =SUM('Working sheet'!$D2:$P2) -> 1371.7 | AG2: =SUM('Working sheet'!$Q2) -> 105.1 | AH2: =SUM('Working sheet'!$R2:$T2) -> 318.7 | AI2: =SUM('Working sheet'!$U2) -> 100.4 | AJ2: =SUM('Working sheet'!$V2) -> 105.5 | AK2: =SUM('Working sheet'!$W2:$AC2) -> 728
A3: Urban | B3: 2013 | C3: January | D3: 110.5 | E3: 109.1 | F3: 113 | G3: 103.6 | H3: 103.4 | I3: 102.3 | J3: 102.9 | K3: 105.8 | L3: 105.1 | M3: 101.8 | N3: 105.1 | O3: 107.9 | P3: 105.9 | Q3: 105.2 | R3: 105.9 | S3: 105 | T3: 105.8 | U3: 100.3 | V3: 105.4 | W3: 104.8 | X3: 104.1 | Y3: 103.2 | Z3: 102.9 | AA3: 103.5 | AB3: 104.3 | AC3: 103.7 | AD3: 104 | AF3: =SUM('Working sheet'!$D3:$P3) -> 1376.4 | AG3: =SUM('Working sheet'!$Q3) -> 105.2 | AH3: =SUM('Working sheet'!$R3:$T3) -> 316.7 | AI3: =SUM('Working sheet'!$U3) -> 100.3 | AJ3: =SUM('Working sheet'!$V3) -> 105.4 | AK3: =SUM('Working sheet'!$W3:$AC3) -> 726.5
A4: Rural+Urban | B4: 2013 | C4: January | D4: 108.4 | E4: 107.3 | F4: 110 | G4: 104.4 | H4: 105.1 | I4: 103.2 | J4: 102.2 | K4: 106 | L4: 106.2 | M4: 102.7 | N4: 104.9 | O4: 107.3 | P4: 105.6 | Q4: 105.1 | R4: 106.3 | S4: 105.5 | T4: 106.2 | U4: 100.3 | V4: 105.5 | W4: 104.8 | X4: 104 | Y4: 103.2 | Z4: 103.1 | AA4: 103.6 | AB4: 104.5 | AC4: 103.9 | AD4: 104.6 | AF4: =SUM('Working sheet'!$D4:$P4) -> 1373.3 | AG4: =SUM('Working sheet'!$Q4) -> 105.1 | AH4: =SUM('Working sheet'!$R4:$T4) -> 318 | AI4: =SUM('Working sheet'!$U4) -> 100.3 | AJ4: =SUM('Working sheet'!$V4) -> 105.5 | AK4: =SUM('Working sheet'!$W4:$AC4) -> 727.1
A5: Rural | B5: 2013 | C5: February | D5: 109.2 | E5: 108.7 | F5: 110.2 | G5: 105.4 | H5: 106.7 | I5: 104 | J5: 102.4 | K5: 105.9 | L5: 105.7 | M5: 103.1 | N5: 105.1 | O5: 107.7 | P5: 106.3 | Q5: 105.6 | R5: 107.1 | S5: 106.3 | T5: 107 | U5: 100.4 | V5: 106.2 | W5: 105.2 | X5: 104.4 | Y5: 103.9 | Z5: 104 | AA5: 104.1 | AB5: 104.6 | AC5: 104.4 | AD5: 105.8 | AF5: =SUM('Working sheet'!$D5:$P5) -> 1380.4 | AG5: =SUM('Working sheet'!$Q5) -> 105.6 | AH5: =SUM('Working sheet'!$R5:$T5) -> 320.4 | AI5: =SUM('Working sheet'!$U5) -> 100.4 | AJ5: =SUM('Working sheet'!$V5) -> 106.2 | AK5: =SUM('Working sheet'!$W5:$AC5) -> 730.6
A6: Urban | B6: 2013 | C6: February | D6: 112.9 | E6: 112.9 | F6: 116.9 | G6: 104 | H6: 103.5 | I6: 103.1 | J6: 104.9 | K6: 104.1 | L6: 103.8 | M6: 102.3 | N6: 106 | O6: 109 | P6: 107.2 | Q6: 106 | R6: 106.6 | S6: 105.5 | T6: 106.4 | U6: 100.4 | V6: 105.7 | W6: 105.2 | X6: 104.7 | Y6: 104.4 | Z6: 103.3 | AA6: 103.7 | AB6: 104.3 | AC6: 104.3 | AD6: 104.7 | AF6: =SUM('Working sheet'!$D6:$P6) -> 1390.6 | AG6: =SUM('Working sheet'!$Q6) -> 106 | AH6: =SUM('Working sheet'!$R6:$T6) -> 318.5 | AI6: =SUM('Working sheet'!$U6) -> 100.4 | AJ6: =SUM('Working sheet'!$V6) -> 105.7 | AK6: =SUM('Working sheet'!$W6:$AC6) -> 729.9
A7: Rural+Urban | B7: 2013 | C7: February | D7: 110.4 | E7: 110.2 | F7: 112.8 | G7: 104.9 | H7: 105.5 | I7: 103.6 | J7: 103.2 | K7: 105.3 | L7: 105.1 | M7: 102.8 | N7: 105.5 | O7: 108.3 | P7: 106.6 | Q7: 105.7 | R7: 106.9 | S7: 106 | T7: 106.8 | U7: 100.4 | V7: 106 | W7: 105.2 | X7: 104.5 | Y7: 104.2 | Z7: 103.6 | AA7: 103.9 | AB7: 104.5 | AC7: 104.4 | AD7: 105.3 | AF7: =SUM('Working sheet'!$D7:$P7) -> 1384.2 | AG7: =SUM('Working sheet'!$Q7) -> 105.7 | AH7: =SUM('Working sheet'!$R7:$T7) -> 319.7 | AI7: =SUM('Working sheet'!$U7) -> 100.4 | AJ7: =SUM('Working sheet'!$V7) -> 106 | AK7: =SUM('Working sheet'!$W7:$AC7) -> 730.3
A8: Rural | B8: 2013 | C8: March | D8: 110.2 | E8: 108.8 | F8: 109.9 | G8: 105.6 | H8: 106.2 | I8: 105.7 | J8: 101.4 | K8: 105.7 | L8: 105 | M8: 103.3 | N8: 105.6 | O8: 108.2 | P8: 106.6 | Q8: 106.5 | R8: 107.6 | S8: 106.8 | T8: 107.5 | U8: 100.5 | V8: 106.1 | W8: 105.6 | X8: 104.7 | Y8: 104.6 | Z8: 104 | AA8: 104.3 | AB8: 104.3 | AC8: 104.6 | AD8: 106 | AF8: =SUM('Working sheet'!$D8:$P8) -> 1382.2 | AG8: =SUM('Working sheet'!$Q8) -> 106.5 | AH8: =SUM('Working sheet'!$R8:$T8) -> 321.9 | AI8: =SUM('Working sheet'!$U8) -> 100.5 | AJ8: =SUM('Working sheet'!$V8) -> 106.1 | AK8: =SUM('Working sheet'!$W8:$AC8) -> 732.1
A9: Urban | B9: 2013 | C9: March | D9: 113.9 | E9: 111.4 | F9: 113.2 | G9: 104.3 | H9: 102.7 | I9: 104.9 | J9: 103.8 | K9: 103.5 | L9: 102.6 | M9: 102.4 | N9: 107 | O9: 109.8 | P9: 107.3 | Q9: 106.8 | R9: 107.2 | S9: 106 | T9: 107 | U9: 100.4 | V9: 106 | W9: 105.7 | X9: 105.2 | Y9: 105.5 | Z9: 103.5 | AA9: 103.8 | AB9: 104.2 | AC9: 104.9 | AD9: 105 | AF9: =SUM('Working sheet'!$D9:$P9) -> 1386.8 | AG9: =SUM('Working sheet'!$Q9) -> 106.8 | AH9: =SUM('Working sheet'!$R9:$T9) -> 320.2 | AI9: =SUM('Working sheet'!$U9) -> 100.4 | AJ9: =SUM('Working sheet'!$V9) -> 106 | AK9: =SUM('Working sheet'!$W9:$AC9) -> 732.8
A10: Rural+Urban | B10: 2013 | C10: March | D10: 111.4 | E10: 109.7 | F10: 111.2 | G10: 105.1 | H10: 104.9 | I10: 105.3 | J10: 102.2 | K10: 105 | L10: 104.2 | M10: 103 | N10: 106.2 | O10: 108.9 | P10: 106.9 | Q10: 106.6 | R10: 107.4 | S10: 106.5 | T10: 107.3 | U10: 100.4 | V10: 106.1 | W10: 105.6 | X10: 104.9 | Y10: 105.1 | Z10: 103.7 | AA10: 104 | AB10: 104.3 | AC10: 104.7 | AD10: 105.5 | AF10: =SUM('Working sheet'!$D10:$P10) -> 1384 | AG10: =SUM('Working sheet'!$Q10) -> 106.6 | AH10: =SUM('Working sheet'!$R10:$T10) -> 321.2 | AI10: =SUM('Working sheet'!$U10) -> 100.4 | AJ10: =SUM('Working sheet'!$V10) -> 106.1 | AK10: =SUM('Working sheet'!$W10:$AC10) -> 732.3
A11: Rural | B11: 2013 | C11: April | D11: 110.2 | E11: 109.5 | F11: 106.9 | G11: 106.3 | H11: 105.7 | I11: 108.3 | J11: 103.4 | K11: 105.7 | L11: 104.2 | M11: 103.2 | N11: 106.5 | O11: 108.8 | P11: 107.1 | Q11: 107.1 | R11: 108.1 | S11: 107.4 | T11: 108 | U11: 100.5 | V11: 106.5 | W11: 106.1 | X11: 105.1 | Y11: 104.4 | Z11: 104.5 | AA11: 104.8 | AB11: 102.7 | AC11: 104.6 | AD11: 106.4 | AF11: =SUM('Working sheet'!$D11:$P11) -> 1385.8 | AG11: =SUM('Working sheet'!$Q11) -> 107.1 | AH11: =SUM('Working sheet'!$R11:$T11) -> 323.5 | AI11: =SUM('Working sheet'!$U11) -> 100.5 | AJ11: =SUM('Working sheet'!$V11) -> 106.5 | AK11: =SUM('Working sheet'!$W11:$AC11) -> 732.2
A12: Urban | B12: 2013 | C12: April | D12: 114.6 | E12: 113.4 | F12: 106 | G12: 104.7 | H12: 102.1 | I12: 109.5 | J12: 109.7 | K12: 104.6 | L12: 102 | M12: 103.5 | N12: 108.2 | O12: 110.6 | P12: 108.8 | Q12: 108.5 | R12: 107.9 | S12: 106.4 | T12: 107.7 | U12: 100.5 | V12: 106.4 | W12: 106.5 | X12: 105.7 | Y12: 105 | Z12: 104 | AA12: 105.2 | AB12: 103.2 | AC12: 105.1 | AD12: 105.7 | AF12: =SUM('Working sheet'!$D12:$P12) -> 1397.7 | AG12: =SUM('Working sheet'!$Q12) -> 108.5 | AH12: =SUM('Working sheet'!$R12:$T12) -> 322 | AI12: =SUM('Working sheet'!$U12) -> 100.5 | AJ12: =SUM('Working sheet'!$V12) -> 106.4 | AK12: =SUM('Working sheet'!$W12:$AC12) -> 734.7
A13: Rural+Urban | B13: 2013 | C13: April | D13: 111.6 | E13: 110.9 | F13: 106.6 | G13: 105.7 | H13: 104.4 | I13: 108.9 | J13: 105.5 | K13: 105.3 | L13: 103.5 | M13: 103.3 | N13: 107.2 | O13: 109.6 | P13: 107.7 | Q13: 107.5 | R13: 108 | S13: 107 | T13: 107.9 | U13: 100.5 | V13: 106.5 | W13: 106.3 | X13: 105.3 | Y13: 104.7 | Z13: 104.2 | AA13: 105 | AB13: 102.9 | AC13: 104.8 | AD13: 106.1 | AF13: =SUM('Working sheet'!$D13:$P13) -> 1390.2 | AG13: =SUM('Working sheet'!$Q13) -> 107.5 | AH13: =SUM('Working sheet'!$R13:$T13) -> 322.9 | AI13: =SUM('Working sheet'!$U13) -> 100.5 | AJ13: =SUM('Working sheet'!$V13) -> 106.5 | AK13: =SUM('Working sheet'!$W13:$AC13) -> 733.2
... A292: Rural+Urban | B292: 2021 | C292: February | D292: 144.3 | E292: 186.5 | F292: 168.7 | G292: 154.7 | H292: 158.7 | I292: 150.7 | J292: 160 | K292: 158.8 | L292: 112.8 | M292: 164.2 | N292: 155.5 | O292: 167.5 | P292: 156.9 | Q292: 188.3 | R292: 157.2 | S292: 147.4 | T292: 155.8 | U292: 159.8 | V292: 152.4 | W292: 150.9 | X292: 161.3 | Y292: 145.1 | Z292: 151.5 | AA292: 159.5 | AB292: 155.8 | AC292: 153.4 | AD292: 156.6 | AF292: =SUM('Working sheet'!$D292:$P292) -> 2039.3 | AG292: =SUM('Working sheet'!$Q292) -> 188.3 | AH292: =SUM('Working sheet'!$R292:$T292) -> 460.4 | AI292: =SUM('Working sheet'!$U292) -> 159.8 | AJ292: =SUM('Working sheet'!$V292) -> 152.4 | AK292: =SUM('Working sheet'!$W292:$AC292) -> 1077.5
A293: Rural | B293: 2021 | C293: March | D293: 142.5 | E293: 189.4 | F293: 163.2 | G293: 154.5 | H293: 168.2 | I293: 150.5 | J293: 141 | K293: 159.2 | L293: 111.7 | M293: 164 | N293: 160.6 | O293: 166.4 | P293: 154.5 | Q293: 186.1 | R293: 159.6 | S293: 154.4 | T293: 158.9 | U293: - | V293: 156 | W293: 154.8 | X293: 164.6 | Y293: 151.3 | Z293: 157.8 | AA293: 163.8 | AB293: 153.1 | AC293: 157.3 | AD293: 156.7 | AF293: =SUM('Working sheet'!$D293:$P293) -> 2025.7 | AG293: =SUM('Working sheet'!$Q293) -> 186.1 | AH293: =SUM('Working sheet'!$R293:$T293) -> 472.9 | AI293: =SUM('Working sheet'!$U293) -> 0 | AJ293: =SUM('Working sheet'!$V293) -> 156 | AK293: =SUM('Working sheet'!$W293:$AC293) -> 1102.7
A294: Urban | B294: 2021 | C294: March | D294: 147.5 | E294: 197.5 | F294: 164.7 | G294: 155.6 | H294: 156.4 | I294: 157.3 | J294: 166.1 | K294: 161.1 | L294: 114.3 | M294: 162.6 | N294: 150.7 | O294: 170.3 | P294: 160.4 | Q294: 193.5 | R294: 155.1 | S294: 138.7 | T294: 152.6 | U294: 159.9 | V294: 154.8 | W294: 147.2 | X294: 156.9 | Y294: 141.7 | Z294: 148.6 | AA294: 157.6 | AB294: 154.9 | AC294: 150 | AD294: 156.9 | AF294: =SUM('Working sheet'!$D294:$P294) -> 2064.5 | AG294: =SUM('Working sheet'!$Q294) -> 193.5 | AH294: =SUM('Working sheet'!$R294:$T294) -> 446.4 | AI294: =SUM('Working sheet'!$U294) -> 159.9 | AJ294: =SUM('Working sheet'!$V294) -> 154.8 | AK294: =SUM('Working sheet'!$W294:$AC294) -> 1056.9
A295: Rural+Urban | B295: 2021 | C295: March | D295: 144.1 | E295: 192.2 | F295: 163.8 | G295: 154.9 | H295: 163.9 | I295: 153.7 | J295: 149.5 | K295: 159.8 | L295: 112.6 | M295: 163.5 | N295: 156.5 | O295: 168.2 | P295: 156.7 | Q295: 188.1 | R295: 157.8 | S295: 147.9 | T295: 156.4 | U295: 159.9 | V295: 155.5 | W295: 151.2 | X295: 161.7 | Y295: 146.2 | Z295: 152.6 | AA295: 160.2 | AB295: 153.8 | AC295: 153.8 | AD295: 156.8 | AF295: =SUM('Working sheet'!$D295:$P295) -> 2039.4 | AG295: =SUM('Working sheet'!$Q295) -> 188.1 | AH295: =SUM('Working sheet'!$R295:$T295) -> 462.1 | AI295: =SUM('Working sheet'!$U295) -> 159.9 | AJ295: =SUM('Working sheet'!$V295) -> 155.5 | AK295: =SUM('Working sheet'!$W295:$AC295) -> 1079.5
A296: Rural | B296: 2021 | C296: April | D296: 142.7 | E296: 195.5 | F296: 163.4 | G296: 155 | H296: 175.2 | I296: 160.6 | J296: 135.1 | K296: 161.1 | L296: 112.2 | M296: 164.4 | N296: 161.9 | O296: 166.8 | P296: 155.6 | Q296: 186.8 | R296: 160.7 | S296: 155.1 | T296: 159.9 | U296: - | V296: 156 | W296: 155.5 | X296: 165.3 | Y296: 151.7 | Z296: 158.6 | AA296: 164.1 | AB296: 154.6 | AC296: 158 | AD296: 157.6 | AF296: =SUM('Working sheet'!$D296:$P296) -> 2049.5 | AG296: =SUM('Working sheet'!$Q296) -> 186.8 | AH296: =SUM('Working sheet'!$R296:$T296) -> 475.7 | AI296: =SUM('Working sheet'!$U296) -> 0 | AJ296: =SUM('Working sheet'!$V296) -> 156 | AK296: =SUM('Working sheet'!$W296:$AC296) -> 1107.8
A297: Urban | B297: 2021 | C297: April | D297: 147.6 | E297: 202.5 | F297: 166.4 | G297: 156 | H297: 161.4 | I297: 168.8 | J297: 161.6 | K297: 162.8 | L297: 114.8 | M297: 162.8 | N297: 151.5 | O297: 171.4 | P297: 162 | Q297: 194.4 | R297: 155.9 | S297: 139.3 | T297: 153.4 | U297: 161.4 | V297: 154.9 | W297: 147.6 | X297: 157.5 | Y297: 142.1 | Z297: 149.1 | AA297: 157.6 | AB297: 156.6 | AC297: 150.5 | AD297: 158 | AF297: =SUM('Working sheet'!$D297:$P297) -> 2089.6 | AG297: =SUM('Working sheet'!$Q297) -> 194.4 | AH297: =SUM('Working sheet'!$R297:$T297) -> 448.6 | AI297: =SUM('Working sheet'!$U297) -> 161.4 | AJ297: =SUM('Working sheet'!$V297) -> 154.9 | AK297: =SUM('Working sheet'!$W297:$AC297) -> 1061
A298: Rural+Urban | B298: 2021 | C298: April | D298: 144.3 | E298: 198 | F298: 164.6 | G298: 155.4 | H298: 170.1 | I298: 164.4 | J298: 144.1 | K298: 161.7 | L298: 113.1 | M298: 163.9 | N298: 157.6 | O298: 168.9 | P298: 158 | Q298: 188.8 | R298: 158.8 | S298: 148.5 | T298: 157.3 | U298: 161.4 | V298: 155.6 | W298: 151.8 | X298: 162.3 | Y298: 146.6 | Z298: 153.2 | AA298: 160.3 | AB298: 155.4 | AC298: 154.4 | AD298: 157.8 | AF298: =SUM('Working sheet'!$D298:$P298) -> 2064.1 | AG298: =SUM('Working sheet'!$Q298) -> 188.8 | AH298: =SUM('Working sheet'!$R298:$T298) -> 464.6 | AI298: =SUM('Working sheet'!$U298) -> 161.4 | AJ298: =SUM('Working sheet'!$V298) -> 155.6 | AK298: =SUM('Working sheet'!$W298:$AC298) -> 1084
A299: Rural | B299: 2021 | C299: May | D299: 145.1 | E299: 198.5 | F299: 168.6 | G299: 155.8 | H299: 184.4 | I299: 162.3 | J299: 138.4 | K299: 165.1 | L299: 114.3 | M299: 169.7 | N299: 164.6 | O299: 169.8 | P299: 158.7 | Q299: 189.6 | R299: 165.3 | S299: 160.6 | T299: 164.5 | U299: 161.1 | V299: 161.7 | W299: 158.8 | X299: 169.1 | Y299: 153.2 | Z299: 160 | AA299: 167.6 | AB299: 159.3 | AC299: 161.1 | AD299: 161.1 | AF299: =SUM('Working sheet'!$D299:$P299) -> 2095.3 | AG299: =SUM('Working sheet'!$Q299) -> 189.6 | AH299: =SUM('Working sheet'!$R299:$T299) -> 490.4 | AI299: =SUM('Working sheet'!$U299) -> 161.1 | AJ299: =SUM('Working sheet'!$V299) -> 161.7 | AK299: =SUM('Working sheet'!$W299:$AC299) -> 1129.1
A300: Urban | B300: 2021 | C300: May | D300: 148.8 | E300: 204.3 | F300: 173 | G300: 156.5 | H300: 168.8 | I300: 172.5 | J300: 166.5 | K300: 165.9 | L300: 115.9 | M300: 165.2 | N300: 152 | O300: 171.1 | P300: 164.2 | Q300: 198.2 | R300: 156.5 | S300: 140.2 | T300: 154.1 | U300: 161.6 | V300: 155.5 | W300: 150.1 | X300: 160.4 | Y300: 145 | Z300: 152.6 | AA300: 156.6 | AB300: 157.5 | AC300: 152.3 | AD300: 159.5 | AF300: =SUM('Working sheet'!$D300:$P300) -> 2124.7 | AG300: =SUM('Working sheet'!$Q300) -> 198.2 | AH300: =SUM('Working sheet'!$R300:$T300) -> 450.8 | AI300: =SUM('Working sheet'!$U300) -> 161.6 | AJ300: =SUM('Working sheet'!$V300) -> 155.5 | AK300: =SUM('Working sheet'!$W300:$AC300) -> 1074.5
A301: Rural+Urban | B301: 2021 | C301: May | D301: 146.3 | E301: 200.5 | F301: 170.3 | G301: 156.1 | H301: 178.7 | I301: 167.1 | J301: 147.9 | K301: 165.4 | L301: 114.8 | M301: 168.2 | N301: 159.3 | O301: 170.4 | P301: 160.7 | Q301: 191.9 | R301: 161.8 | S301: 152.1 | T301: 160.4 | U301: 161.6 | V301: 159.4 | W301: 154.7 | X301: 165.8 | Y301: 148.9 | Z301: 155.8 | AA301: 161.2 | AB301: 158.6 | AC301: 156.8 | AD301: 160.4 | AF301: =SUM('Working sheet'!$D301:$P301) -> 2105.7 | AG301: =SUM('Working sheet'!$Q301) -> 191.9 | AH301: =SUM('Working sheet'!$R301:$T301) -> 474.3 | AI301: =SUM('Working sheet'!$U301) -> 161.6 | AJ301: =SUM('Working sheet'!$V301) -> 159.4 | AK301: =SUM('Working sheet'!$W301:$AC301) -> 1101.8
A302: Rural | B302: 2021 | C302: June | D302: 145.6 | E302: 200.1 | F302: 179.3 | G302: 156.1 | H302: 190.4 | I302: 158.6 | J302: 144.7 | K302: 165.5 | L302: 114.6 | M302: 170 | N302: 165.5 | O302: 171.7 | P302: 160.5 | Q302: 189.1 | R302: 165.3 | S302: 159.9 | T302: 164.6 | U302: 161 | V302: 162.1 | W302: 159.2 | X302: 169.7 | Y302: 154.2 | Z302: 160.4 | AA302: 166.8 | AB302: 159.4 | AC302: 161.5 | AD302: 162.1 | AF302: =SUM('Working sheet'!$D302:$P302) -> 2122.6 | AG302: =SUM('Working sheet'!$Q302) -> 189.1 | AH302: =SUM('Working sheet'!$R302:$T302) -> 489.8 | AI302: =SUM('Working sheet'!$U302) -> 161 | AJ302: =SUM('Working sheet'!$V302) -> 162.1 | AK302: =SUM('Working sheet'!$W302:$AC302) -> 1131.2
A303: Urban | B303: 2021 | C303: June | D303: 149.2 | E303: 205.5 | F303: 182.8 | G303: 156.5 | H303: 172.2 | I303: 171.5 | J303: 176.2 | K303: 166.9 | L303: 116.1 | M303: 165.5 | N303: 152.3 | O303: 173.3 | P303: 166.2 | Q303: 195.6 | R303: 157.3 | S303: 140.5 | T303: 154.8 | U303: 160.5 | V303: 156.1 | W303: 149.8 | X303: 160.8 | Y303: 147.5 | Z303: 150.7 | AA303: 158.1 | AB303: 158 | AC303: 153.4 | AD303: 160.4 | AF303: =SUM('Working sheet'!$D303:$P303) -> 2154.2 | AG303: =SUM('Working sheet'!$Q303) -> 195.6 | AH303: =SUM('Working sheet'!$R303:$T303) -> 452.6 | AI303: =SUM('Working sheet'!$U303) -> 160.5 | AJ303: =SUM('Working sheet'!$V303) -> 156.1 | AK303: =SUM('Working sheet'!$W303:$AC303) -> 1078.3
A304: Rural+Urban | B304: 2021 | C304: June | D304: 146.7 | E304: 202 | F304: 180.7 | G304: 156.2 | H304: 183.7 | I304: 164.6 | J304: 155.4 | K304: 166 | L304: 115.1 | M304: 168.5 | N304: 160 | O304: 172.4 | P304: 162.6 | Q304: 190.8 | R304: 162.2 | S304: 151.8 | T304: 160.7 | U304: 160.5 | V304: 159.8 | W304: 154.8 | X304: 166.3 | Y304: 150.7 | Z304: 154.9 | AA304: 161.7 | AB304: 158.8 | AC304: 157.6 | AD304: 161.3 | AF304: =SUM('Working sheet'!$D304:$P304) -> 2133.9 | AG304: =SUM('Working sheet'!$Q304) -> 190.8 | AH304: =SUM('Working sheet'!$R304:$T304) -> 474.7 | AI304: =SUM('Working sheet'!$U304) -> 160.5 | AJ304: =SUM('Working sheet'!$V304) -> 159.8 | AK304: =SUM('Working sheet'!$W304:$AC304) -> 1104.8
A305: Rural | B305: 2021 | C305: July | D305: 145.1 | E305: 204.5 | F305: 180.4 | G305: 157.1 | H305: 188.7 | I305: 157.7 | J305: 152.8 | K305: 163.6 | L305: 113.9 | M305: 169.7 | N305: 166.2 | O305: 171 | P305: 161.7 | Q305: 189.7 | R305: 166 | S305: 161.1 | T305: 165.3 | U305: 161.8 | V305: 162.5 | W305: 160.3 | X305: 170.4 | Y305: 157.1 | Z305: 160.7 | AA305: 167.2 | AB305: 160.4 | AC305: 162.8 | AD305: 163.2 | AF305: =SUM('Working sheet'!$D305:$P305) -> 2132.4 | AG305: =SUM('Working sheet'!$Q305) -> 189.7 | AH305: =SUM('Working sheet'!$R305:$T305) -> 492.4 | AI305: =SUM('Working sheet'!$U305) -> 161.8 | AJ305: =SUM('Working sheet'!$V305) -> 162.5 | AK305: =SUM('Working sheet'!$W305:$AC305) -> 1138.9
A306: Urban | B306: 2021 | C306: July | D306: 149.1 | E306: 210.9 | F306: 185 | G306: 158.2 | H306: 170.6 | I306: 170.9 | J306: 186.4 | K306: 164.7 | L306: 115.7 | M306: 165.5 | N306: 153.4 | O306: 173.5 | P306: 167.9 | Q306: 195.5 | R306: 157.9 | S306: 141.9 | T306: 155.5 | U306: 161.5 | V306: 157.7 | W306: 150.7 | X306: 161.5 | Y306: 149.5 | Z306: 151.2 | AA306: 160.3 | AB306: 159.6 | AC306: 155 | AD306: 161.8 | AF306: =SUM('Working sheet'!$D306:$P306) -> 2171.8 | AG306: =SUM('Working sheet'!$Q306) -> 195.5 | AH306: =SUM('Working sheet'!$R306:$T306) -> 455.3 | AI306: =SUM('Working sheet'!$U306) -> 161.5 | AJ306: =SUM('Working sheet'!$V306) -> 157.7 | AK306: =SUM('Working sheet'!$W306:$AC306) -> 1087.8
A307: Rural+Urban | B307: 2021 | C307: July | D307: 146.4 | E307: 206.8 | F307: 182.2 | G307: 157.5 | H307: 182.1 | I307: 163.9 | J307: 164.2 | K307: 164 | L307: 114.5 | M307: 168.3 | N307: 160.9 | O307: 172.2 | P307: 164 | Q307: 191.2 | R307: 162.8 | S307: 153.1 | T307: 161.4 | U307: 161.5 | V307: 160.7 | W307: 155.8 | X307: 167 | Y307: 153.1 | Z307: 155.3 | AA307: 163.2 | AB307: 160.1 | AC307: 159 | AD307: 162.5 | AF307: =SUM('Working sheet'!$D307:$P307) -> 2147 | AG307: =SUM('Working sheet'!$Q307) -> 191.2 | AH307: =SUM('Working sheet'!$R307:$T307) -> 477.3 | AI307: =SUM('Working sheet'!$U307) -> 161.5 | AJ307: =SUM('Working sheet'!$V307) -> 160.7 | AK307: =SUM('Working sheet'!$W307:$AC307) -> 1113.5
A308: Rural | B308: 2021 | C308: August | D308: 144.9 | E308: 202.3 | F308: 176.5 | G308: 157.5 | H308: 190.9 | I308: 155.7 | J308: 153.9 | K308: 162.8 | L308: 115.2 | M308: 169.8 | N308: 167.6 | O308: 171.9 | P308: 161.8 | Q308: 190.2 | R308: 167 | S308: 162.6 | T308: 166.3 | U308: 162.1 | V308: 163.1 | W308: 160.9 | X308: 171.1 | Y308: 157.7 | Z308: 161.1 | AA308: 167.5 | AB308: 160.3 | AC308: 163.3 | AD308: 163.6 | AF308: =SUM('Working sheet'!$D308:$P308) -> 2130.8 | AG308: =SUM('Working sheet'!$Q308) -> 190.2 | AH308: =SUM('Working sheet'!$R308:$T308) -> 495.9 | AI308: =SUM('Working sheet'!$U308) -> 162.1 | AJ308: =SUM('Working sheet'!$V308) -> 163.1 | AK308: =SUM('Working sheet'!$W308:$AC308) -> 1141.9
... A373: Rural+Urban | B373: 2023 | C373: May | D373: 173.7 | E373: 214.3 | F373: 173.2 | G373: 179.5 | H373: 170 | I373: 172.2 | J373: 161 | K373: 175.6 | L373: 122.7 | M373: 218 | N373: 173.4 | O373: 194.2 | P373: 179.1 | Q373: 201 | R373: 187.3 | S373: 179.7 | T373: 186.2 | U373: 175.6 | V373: 182.8 | W373: 175.2 | X373: 185.7 | Y373: 164.8 | Z373: 171.2 | AA373: 177.1 | AB373: 185.2 | AC373: 175.7 | AD373: 179.1 | AF373: =SUM('Working sheet'!$D373:$P373) -> 2306.9 | AG373: =SUM('Working sheet'!$Q373) -> 201 | AH373: =SUM('Working sheet'!$R373:$T373) -> 553.2 | AI373: =SUM('Working sheet'!$U373) -> 175.6 | AJ373: =SUM('Working sheet'!$V373) -> 182.8 | AK373: =SUM('Working sheet'!$W373:$AC373) -> 1234.9
A376: 1 | B376: For DA-1, Unpivot all the broader categories in power query.
A377: 2 | B377: https://ppac.gov.in/prices/international-prices-of-crude-oil

Sheet Clean data
A1: Sector | B1: Year | C1: Month | D1: Food & Beverages | E1: Pan, Tobacco & Intoxicants | F1: Clothing & Footwear | G1: Housing | H1: Fuel & Light | I1: Miscellaneous | J1: General index
A2: Rural | B2: 2013 | C2: January | D2: =SUM('Working sheet'!$D2:$P2) -> 1371.7 | E2: =SUM('Working sheet'!$Q2) -> 105.1 | F2: =SUM('Working sheet'!$R2:$T2) -> 318.7 | G2: =SUM('Working sheet'!$U2) -> 100.4 | H2: =SUM('Working sheet'!$V2) -> 105.5 | I2: =SUM('Working sheet'!$W2:$AC2) -> 728 | J2: 105.1
A3: Urban | B3: 2013 | C3: January | D3: =SUM('Working sheet'!$D3:$P3) -> 1376.4 | E3: =SUM('Working sheet'!$Q3) -> 105.2 | F3: =SUM('Working sheet'!$R3:$T3) -> 316.7 | G3: =SUM('Working sheet'!$U3) -> 100.3 | H3: =SUM('Working sheet'!$V3) -> 105.4 | I3: =SUM('Working sheet'!$W3:$AC3) -> 726.5 | J3: 104
A4: Rural+Urban | B4: 2013 | C4: January | D4: =SUM('Working sheet'!$D4:$P4) -> 1373.3 | E4: =SUM('Working sheet'!$Q4) -> 105.1 | F4: =SUM('Working sheet'!$R4:$T4) -> 318 | G4: =SUM('Working sheet'!$U4) -> 100.3 | H4: =SUM('Working sheet'!$V4) -> 105.5 | I4: =SUM('Working sheet'!$W4:$AC4) -> 727.1 | J4: 104.6
A5: Rural | B5: 2013 | C5: February | D5: =SUM('Working sheet'!$D5:$P5) -> 1380.4 | E5: =SUM('Working sheet'!$Q5) -> 105.6 | F5: =SUM('Working sheet'!$R5:$T5) -> 320.4 | G5: =SUM('Working sheet'!$U5) -> 100.4 | H5: =SUM('Working sheet'!$V5) -> 106.2 | I5: =SUM('Working sheet'!$W5:$AC5) -> 730.6 | J5: 105.8
A6: Urban | B6: 2013 | C6: February | D6: =SUM('Working sheet'!$D6:$P6) -> 1390.6 | E6: =SUM('Working sheet'!$Q6) -> 106 | F6: =SUM('Working sheet'!$R6:$T6) -> 318.5 | G6: =SUM('Working sheet'!$U6) -> 100.4 | H6: =SUM('Working sheet'!$V6) -> 105.7 | I6: =SUM('Working sheet'!$W6:$AC6) -> 729.9 | J6: 104.7
A7: Rural+Urban | B7: 2013 | C7: February | D7: =SUM('Working sheet'!$D7:$P7) -> 1384.2 | E7: =SUM('Working sheet'!$Q7) -> 105.7 | F7: =SUM('Working sheet'!$R7:$T7) -> 319.7 | G7: =SUM('Working sheet'!$U7) -> 100.4 | H7: =SUM('Working sheet'!$V7) -> 106 | I7: =SUM('Working sheet'!$W7:$AC7) -> 730.3 | J7: 105.3
A8: Rural | B8: 2013 | C8: March | D8: =SUM('Working sheet'!$D8:$P8) -> 1382.2 | E8: =SUM('Working sheet'!$Q8) -> 106.5 | F8: =SUM('Working sheet'!$R8:$T8) -> 321.9 | G8: =SUM('Working sheet'!$U8) -> 100.5 | H8: =SUM('Working sheet'!$V8) -> 106.1 | I8: =SUM('Working sheet'!$W8:$AC8) -> 732.1 | J8: 106
A9: Urban | B9: 2013 | C9: March | D9: =SUM('Working sheet'!$D9:$P9) -> 1386.8 | E9: =SUM('Working sheet'!$Q9) -> 106.8 | F9: =SUM('Working sheet'!$R9:$T9) -> 320.2 | G9: =SUM('Working sheet'!$U9) -> 100.4 | H9: =SUM('Working sheet'!$V9) -> 106 | I9: =SUM('Working sheet'!$W9:$AC9) -> 732.8 | J9: 105
A10: Rural+Urban | B10: 2013 | C10: March | D10: =SUM('Working sheet'!$D10:$P10) -> 1384 | E10: =SUM('Working sheet'!$Q10) -> 106.6 | F10: =SUM('Working sheet'!$R10:$T10) -> 321.2 | G10: =SUM('Working sheet'!$U10) -> 100.4 | H10: =SUM('Working sheet'!$V10) -> 106.1 | I10: =SUM('Working sheet'!$W10:$AC10) -> 732.3 | J10: 105.5
A11: Rural | B11: 2013 | C11: April | D11: =SUM('Working sheet'!$D11:$P11) -> 1385.8 | E11: =SUM('Working sheet'!$Q11) -> 107.1 | F11: =SUM('Working sheet'!$R11:$T11) -> 323.5 | G11: =SUM('Working sheet'!$U11) -> 100.5 | H11: =SUM('Working sheet'!$V11) -> 106.5 | I11: =SUM('Working sheet'!$W11:$AC11) -> 732.2 | J11: 106.4
A12: Urban | B12: 2013 | C12: April | D12: =SUM('Working sheet'!$D12:$P12) -> 1397.7 | E12: =SUM('Working sheet'!$Q12) -> 108.5 | F12: =SUM('Working sheet'!$R12:$T12) -> 322 | G12: =SUM('Working sheet'!$U12) -> 100.5 | H12: =SUM('Working sheet'!$V12) -> 106.4 | I12: =SUM('Working sheet'!$W12:$AC12) -> 734.7 | J12: 105.7
A13: Rural+Urban | B13: 2013 | C13: April | D13: =SUM('Working sheet'!$D13:$P13) -> 1390.2 | E13: =SUM('Working sheet'!$Q13) -> 107.5 | F13: =SUM('Working sheet'!$R13:$T13) -> 322.9 | G13: =SUM('Working sheet'!$U13) -> 100.5 | H13: =SUM('Working sheet'!$V13) -> 106.5 | I13: =SUM('Working sheet'!$W13:$AC13) -> 733.2 | J13: 106.1
... A373: Rural+Urban | B373: 2023 | C373: May | D373: =SUM('Working sheet'!$D373:$P373) -> 2306.9 | E373: =SUM('Working sheet'!$Q373) -> 201 | F373: =SUM('Working sheet'!$R373:$T373) -> 553.2 | G373: =SUM('Working sheet'!$U373) -> 175.6 | H373: =SUM('Working sheet'!$V373) -> 182.8 | I373: =SUM('Working sheet'!$W373:$AC373) -> 1234.9 | J373: 179.1

Sheet Classification
B1: Item Name | C1: Indian CPI Category | F1: Food & Beverages
B2: Cereals and products | C2: Food & Beverages | F2: Pan, Tobacco & Intoxicants
B3: Meat and fish | C3: Food & Beverages | F3: Clothing & Footwear
B4: Egg | C4: Food & Beverages | F4: Housing
B5: Milk and products | C5: Food & Beverages | F5: Fuel & Light
B6: Oils and fats | C6: Food & Beverages | F6: Miscellaneous
B7: Fruits | C7: Food & Beverages
B8: Vegetables | C8: Food & Beverages
B9: Pulses and products | C9: Food & Beverages
B10: Sugar and Confectionery | C10: Food & Beverages
B11: Spices | C11: Food & Beverages
B12: Non-alcoholic beverages | C12: Food & Beverages
B13: Prepared meals, snacks, sweets etc. | C13: Food & Beverages
B14: Food and beverages | C14: Food & Beverages
B15: Pan, tobacco and intoxicants | C15: Pan, Tobacco & Intoxicants
B16: Clothing | C16: Clothing & Footwear
B17: Footwear | C17: Clothing & Footwear
B18: Clothing and footwear | C18: Clothing & Footwear
... B28: General index | C28: — Not Categorized

Sheet Case-study overview

Sheet CPI Contribution
A1: Sector | B1: Year | C1: Month | D1: Attribute | E1: Value
A2: Rural | B2: 2013 | C2: January | D2: Food & Beverages | E2: 1371.7
A3: Rural | B3: 2013 | C3: January | D3: Pan, Tobacco & Intoxicants | E3: 105.1
A4: Rural | B4: 2013 | C4: January | D4: Clothing & Footwear | E4: 318.7
A5: Rural | B5: 2013 | C5: January | D5: Housing | E5: 100.4 | H5: Year | I5: 2023
A6: Rural | B6: 2013 | C6: January | D6: Fuel & Light | E6: 105.5 | H6: Month | I6: May
A7: Rural | B7: 2013 | C7: January | D7: Miscellaneous | E7: 728
A8: Urban | B8: 2013 | C8: January | D8: Food & Beverages | E8: 1376.4 | I8: Column Labels
A9: Urban | B9: 2013 | C9: January | D9: Pan, Tobacco & Intoxicants | E9: 105.2 | I9: Rural+Urban
A10: Urban | B10: 2013 | C10: January | D10: Clothing & Footwear | E10: 316.7 | H10: Categories | I10: Index values | J10: Percentage
A11: Urban | B11: 2013 | C11: January | D11: Housing | E11: 100.3 | H11: Clothing & Footwear | I11: 553.2 | J11: 0.11885528
A12: Urban | B12: 2013 | C12: January | D12: Fuel & Light | E12: 105.4 | H12: Food & Beverages | I12: 2306.9 | J12: 0.49563854
A13: Urban | B13: 2013 | C13: January | D13: Miscellaneous | E13: 726.5 | H13: Fuel & Light | I13: 182.8 | J13: 0.039274665
A14: Rural+Urban | B14: 2013 | C14: January | D14: Food & Beverages | E14: 1373.3 | H14: Housing | I14: 175.6 | J14: 0.037727741
A15: Rural+Urban | B15: 2013 | C15: January | D15: Pan, Tobacco & Intoxicants | E15: 105.1 | H15: Miscellaneous | I15: 1234.9 | J15: 0.26531884
A16: Rural+Urban | B16: 2013 | C16: January | D16: Clothing & Footwear | E16: 318 | H16: Pan, Tobacco & Intoxicants | I16: 201 | J16: 0.043184943
A17: Rural+Urban | B17: 2013 | C17: January | D17: Housing | E17: 100.3 | H17: Grand Total | I17: 4654.4 | J17: 1
A18: Rural+Urban | B18: 2013 | C18: January | D18: Fuel & Light | E18: 105.5
A19: Rural+Urban | B19: 2013 | C19: January | D19: Miscellaneous | E19: 727.1
A20: Rural | B20: 2013 | C20: February | D20: Food & Beverages | E20: 1380.4
A21: Rural | B21: 2013 | C21: February | D21: Pan, Tobacco & Intoxicants | E21: 105.6
A22: Rural | B22: 2013 | C22: February | D22: Clothing & Footwear | E22: 320.4
A23: Rural | B23: 2013 | C23: February | D23: Housing | E23: 100.4
A24: Rural | B24: 2013 | C24: February | D24: Fuel & Light | E24: 106.2
A25: Rural | B25: 2013 | C25: February | D25: Miscellaneous | E25: 730.6
A26: Urban | B26: 2013 | C26: February | D26: Food & Beverages | E26: 1390.6
A27: Urban | B27: 2013 | C27: February | D27: Pan, Tobacco & Intoxicants | E27: 106
A28: Urban | B28: 2013 | C28: February | D28: Clothing & Footwear | E28: 318.5
A29: Urban | B29: 2013 | C29: February | D29: Housing | E29: 100.4
... A2233: Rural+Urban | B2233: 2023 | C2233: May | D2233: Miscellaneous | E2233: 1234.9

Sheet YOY Analysis
A1: Year | B1: Y-O-Y difference | C1: Average of General index
A2: 2016 | C2: 129.1
A3: 2017 | B3: 0.033199931 | C3: 133.38611
A4: 2018 | B4: 0.039609321 | C4: 138.66944
A5: 2019 | B5: 0.03935855 | C5: 144.12727
A6: 2020 | B6: 0.062294128 | C6: 153.10556
A7: 2021 | B7: 0.054283537 | C7: 161.41667
A8: 2022 | B8: 0.066029943 | C8: 172.075
A9: 2023 | B9: 0.031953121 | C9: 177.57333
A10: Grand Total | C10: 149.1625
A11: Year | B11: Y-O-Y difference
A12: 2016
A13: 2017 | B13: 0.033199931
A14: 2018 | B14: 0.039609321
A15: 2019 | B15: 0.03935855
A16: 2020 | B16: 0.062294128
A17: 2021 | B17: 0.054283537
A18: 2022 | B18: 0.066029943
A19: 2023 | B19: 0.031953121
A20: Grand Total

Sheet Food Inflation Analysis
A3: Year | B3: Month | C3: Rural | D3: Urban | E3: Rural+Urban | F3: inflation rate | I3: Date | J3: inflation rate | M3: Categories | N3: 44713 | O3: 45047 | P3: Inflation | R3: Categories | S3: Inflation
A4: 2022 | B4: June | C4: 2248.3 | D4: 2287.5 | E4: 2261.9 | I4: Jun-2022 | M4: Cereals and products | N4: 155 | O4: 173.7 | P4: =(O4-N4)/N4*100 -> 12.064516 | R4: Cereals and products | S4: 12.064516
A5: 2022 | B5: July | C5: 2252.5 | D5: 2291.6 | E5: 2266.3 | F5: =(E5-E4)/E4*100 -> 0.19452673 | I5: Jul-2022 | J5: 0.19452673 | M5: Meat and fish | N5: 219.4 | O5: 214.3 | P5: =(O5-N5)/N5*100 -> -2.3245214 | R5: Meat and fish | S5: -2.3245214
A6: 2022 | B6: August | C6: 2255.8 | D6: 2293.7 | E6: 2269.2 | F6: =(E6-E5)/E5*100 -> 0.12796188 | I6: Aug-2022 | J6: 0.12796188 | M6: Egg | N6: 170.8 | O6: 173.2 | P6: =(O6-N6)/N6*100 -> 1.4051522 | R6: Egg | S6: 1.4051522
A7: 2022 | B7: September | C7: 2267.8 | D7: 2306.4 | E7: 2280.9 | F7: =(E7-E6)/E6*100 -> 0.51560021 | I7: Sep-2022 | J7: 0.51560021 | M7: Milk and products | N7: 165.8 | O7: 179.5 | P7: =(O7-N7)/N7*100 -> 8.2629674 | R7: Milk and products | S7: 8.2629674
A8: 2022 | B8: October | C8: 2284.5 | D8: 2322.3 | E8: 2297.3 | F8: =(E8-E7)/E7*100 -> 0.71901442 | I8: Oct-2022 | J8: 0.71901442 | M8: Oils and fats | N8: 200.9 | O8: 170 | P8: =(O8-N8)/N8*100 -> -15.380786 | R8: Oils and fats | S8: -15.380786
A9: 2022 | B9: November | C9: 2287.7 | D9: 2314.4 | E9: 2296.8 | F9: =(E9-E8)/E8*100 -> -0.02176468 | I9: Nov-2022 | J9: -0.02176468 | M9: Fruits | N9: 169.7 | O9: 172.2 | P9: =(O9-N9)/N9*100 -> 1.473188 | R9: Fruits | S9: 1.473188
A10: 2022 | B10: December | C10: 2277.1 | D10: 2295.8 | E10: 2283.4 | F10: =(E10-E9)/E9*100 -> -0.58342041 | I10: Dec-2022 | J10: -0.58342041 | M10: Vegetables | N10: 182.3 | O10: 161 | P10: =(O10-N10)/N10*100 -> -11.684037 | R10: Vegetables | S10: -11.684037
A11: 2023 | B11: January | C11: 2283.2 | D11: 2310.2 | E11: 2292.7 | F11: =(E11-E10)/E10*100 -> 0.40728738 | I11: Jan-2023 | J11: 0.40728738 | M11: Pulses and products | N11: 164.3 | O11: 175.6 | P11: =(O11-N11)/N11*100 -> 6.8776628 | R11: Pulses and products | S11: 6.8776628
A12: 2023 | B12: February | C12: 2265.7 | D12: 2303.2 | E12: 2279.1 | F12: =(E12-E11)/E11*100 -> -0.59318707 | I12: Feb-2023 | J12: -0.59318707 | M12: Sugar and Confectionery | N12: 119.9 | O12: 122.7 | P12: =(O12-N12)/N12*100 -> 2.3352794 | R12: Sugar and Confectionery | S12: 2.3352794
A13: 2023 | B13: March | C13: 2265.8 | D13: 2303.4 | E13: 2279.2 | F13: =(E13-E12)/E12*100 -> 0.0043876969 | I13: Mar-2023 | J13: 0.0043876969 | M13: Spices | N13: 187.1 | O13: 218 | P13: =(O13-N13)/N13*100 -> 16.515232 | R13: Spices | S13: 16.515232
A14: 2023 | B14: April | C14: 2274.2 | D14: 2317.7 | E14: 2289.6 | F14: =(E14-E13)/E13*100 -> 0.45630046 | I14: Apr-2023 | J14: 0.45630046 | M14: Non-alcoholic beverages | N14: 167.9 | O14: 173.4 | P14: =(O14-N14)/N14*100 -> 3.2757594 | R14: Non-alcoholic beverages | S14: 3.2757594
A15: 2023 | B15: May | C15: 2290.7 | D15: 2335.1 | E15: 2306.9 | F15: =(E15-E14)/E14*100 -> 0.7555905 | I15: May-2023 | J15: 0.7555905 | M15: Prepared meals, scks, sweets etc. | N15: 183.9 | O15: 194.2 | P15: =(O15-N15)/N15*100 -> 5.60087 | R15: Prepared meals, scks, sweets etc. | S15: 5.60087
M16: Food and beverages | N16: 174.9 | O16: 179.1 | P16: =(O16-N16)/N16*100 -> 2.4013722 | R16: Food and beverages | S16: 2.4013722

Sheet Covid inflation Analysis
B1: COVID-19 AFFECTED INFLATION RATE IN INDIA
B3: Before Covid | I3: After Covid
A4: Category | B4: Sub Categories | C4: 43525 | D4: 43862 | E4: Inflation | H4: Category | I4: Sub Categories | J4: 43891 | K4: 44228 | L4: Inflation
A5: Food | B5: Cereals and products | C5: 137.8 | D5: 144.8 | E5: =(D5-C5)/C5*100 -> 5.0798258 | H5: Food | I5: Cereals and products | J5: 145.1 | K5: 144.3 | L5: =(K5-J5)/J5*100 -> -0.5513439
A6: Food | B6: Meat and fish | C6: 153 | D6: 167.5 | E6: =(D6-C6)/C6*100 -> 9.4771242 | H6: Food | I6: Meat and fish | J6: 167 | K6: 186.5 | L6: =(K6-J6)/J6*100 -> 11.676647
A7: Food | B7: Egg | C7: 140.3 | D7: 151.8 | E7: =(D7-C7)/C7*100 -> 8.1967213 | H7: Food | I7: Egg | J7: 148.1 | K7: 168.7 | L7: =(K7-J7)/J7*100 -> 13.909521
A8: Food | B8: Milk and products | C8: 142.3 | D8: 150.8 | E8: =(D8-C8)/C8*100 -> 5.9732959 | H8: Food | I8: Milk and products | J8: 151.5 | K8: 154.7 | L8: =(K8-J8)/J8*100 -> 2.1122112
A9: Food | B9: Oils and fats | C9: 122 | D9: 131.4 | E9: =(D9-C9)/C9*100 -> 7.704918 | H9: Food | I9: Oils and fats | J9: 131.2 | K9: 158.7 | L9: =(K9-J9)/J9*100 -> 20.960366
A10: Food | B10: Fruits | C10: 137.6 | D10: 141.8 | E10: =(D10-C10)/C10*100 -> 3.0523256 | H10: Food | I10: Fruits | J10: 142.5 | K10: 150.7 | L10: =(K10-J10)/J10*100 -> 5.754386
A11: Food | B11: Vegetables | C11: 132.6 | D11: 170.7 | E11: =(D11-C11)/C11*100 -> 28.733032 | H11: Food | I11: Vegetables | J11: 157.3 | K11: 160 | L11: =(K11-J11)/J11*100 -> 1.7164654
A12: Food | B12: Pulses and products | C12: 121.8 | D12: 141.1 | E12: =(D12-C12)/C12*100 -> 15.845649 | H12: Food | I12: Pulses and products | J12: 141.1 | K12: 158.8 | L12: =(K12-J12)/J12*100 -> 12.544295
A13: Food | B13: Sugar and Confectionery | C13: 109 | D13: 113.6 | E13: =(D13-C13)/C13*100 -> 4.2201835 | H13: Food | I13: Sugar and Confectionery | J13: 113.2 | K13: 112.8 | L13: =(K13-J13)/J13*100 -> -0.35335689
A14: Food | B14: Spices | C14: 139.5 | D14: 152 | E14: =(D14-C14)/C14*100 -> 8.9605735 | H14: Food | I14: Spices | J14: 153.2 | K14: 164.2 | L14: =(K14-J14)/J14*100 -> 7.1801567
A15: Food | B15: Non-alcoholic beverages | C15: 133.7 | D15: 136.5 | E15: =(D15-C15)/C15*100 -> 2.0942408 | H15: Food | I15: Non-alcoholic beverages | J15: 136.7 | K15: 155.5 | L15: =(K15-J15)/J15*100 -> 13.752743
A16: Food | B16: Prepared meals, scks, sweets etc. | C16: 155.2 | D16: 159.1 | E16: =(D16-C16)/C16*100 -> 2.5128866 | H16: Food | I16: Prepared meals, scks, sweets etc. | J16: 159.6 | K16: 167.5 | L16: =(K16-J16)/J16*100 -> 4.9498747
... A21: Transport | B21: Transport and communication | C21: 124.6 | D21: 130.3 | E21: =(D21-C21)/C21*100 -> 4.5746388 | H21: Transport | I21: Transport and communication | J21: 129.9 | K21: 145.1 | L21: =(K21-J21)/J21*100 -> 11.701309
B23: Inflation rate before Covid | I23: Inflation rate after Covid
A24: Category | B24: Inflation | H24: Category | I24: Inflation
A25: Food | B25: =AVERAGE(E5:E17) -> 8.5253674 | C25: Food | D25: =B25 -> 8.5253674 | H25: Food | I25: =AVERAGE(L5:L17) -> 7.6172844 | J25: Food | K25: =I25 -> 7.6172844
A26: Fuel and light | B26: =E18 -> 5.3686471 | C26: Health | D26: =B28 -> 3.7619699 | H26: Fuel and light | I26: =L18 -> 2.3505709 | J26: Health | K26: =I28 -> 5.9093894
A27: Good and services | B27: =E19 -> 1.8080668 | C27: Essential services | D27: =AVERAGE(B26,B27,B29) -> 3.9171176 | H27: Good and services | I27: =L19 -> 3.0737705 | J27: Essential services | K27: =AVERAGE(I26,I27,I29) -> 5.70855
A28: Health | B28: =E20 -> 3.7619699 | H28: Health | I28: =L20 -> 5.9093894
A29: Transport | B29: =E21 -> 4.5746388 | H29: Transport | I29: =L21 -> 11.701309

Sheet Crude oil Analysis
A6: Year | B6: Month | C6: Food & Beverages | D6: Pan, Tobacco & Intoxicants | E6: Clothing & Footwear | F6: Housing | G6: Fuel & Light | H6: Household goods and services | I6: Health | J6: Transport and communication | K6: Recreation and amusement | L6: Education | M6: Persol care and effects | N6: Miscellaneous | O6: Crude oil | Q6: Food & Beverages | R6: Pan, Tobacco & Intoxicants | S6: Clothing & Footwear | T6: Housing | U6: Fuel & Light | V6: Household goods and services | W6: Health | X6: Transport and communication | Y6: Recreation and amusement | Z6: Education | AA6: Persol care and effects | AB6: Miscellaneous
A7: 2021 | B7: January | C7: 2076.5 | D7: 186.5 | E7: 455.8 | F7: 157.7 | G7: 147.9 | H7: 150 | I7: 159.3 | J7: 141.9 | K7: 149.6 | L7: 159.2 | M7: 156.8 | N7: 151.9 | O7: 54.79457 | Q7: =CORREL(C7:C35,$O$7:$O$35) -> 0.58420485 | R7: =CORREL(D7:D35,$O$7:$O$35) -> 0.3988405 | S7: =CORREL(E7:E35,$O$7:$O$35) -> 0.53102217 | T7: =CORREL(F7:F35,$O$7:$O$35) -> 0.42782963 | U7: =CORREL(G7:G35,$O$7:$O$35) -> 0.57024198 | V7: =CORREL(H7:H35,$O$7:$O$35) -> 0.50593742 | W7: =CORREL(I7:I35,$O$7:$O$35) -> 0.47641008 | X7: =CORREL(J7:J35,$O$7:$O$35) -> 0.66761514 | ... AB7: =CORREL(N7:N35,$O$7:$O$35) -> 0.53388059
A8: 2021 | B8: February | C8: 2039.3 | D8: 188.3 | E8: 460.4 | F8: 159.8 | G8: 152.4 | H8: 150.9 | I8: 161.3 | J8: 145.1 | K8: 151.5 | L8: 159.5 | M8: 155.8 | N8: 153.4 | O8: 61.216117
A9: 2021 | B9: March | C9: 2039.4 | D9: 188.1 | E9: 462.1 | F9: 159.9 | G9: 155.5 | H9: 151.2 | I9: 161.7 | J9: 146.2 | K9: 152.6 | L9: 160.2 | M9: 153.8 | N9: 153.8 | O9: 64.729497
A10: 2021 | B10: April | C10: 2064.1 | D10: 188.8 | E10: 464.6 | F10: 161.4 | G10: 155.6 | H10: 151.8 | I10: 162.3 | J10: 146.6 | K10: 153.2 | L10: 160.3 | M10: 155.4 | N10: 154.4 | O10: 63.396977
A11: 2021 | B11: May | C11: 2105.7 | D11: 191.9 | E11: 474.3 | F11: 161.6 | G11: 159.4 | H11: 154.7 | I11: 165.8 | J11: 148.9 | K11: 155.8 | L11: 161.2 | M11: 158.6 | N11: 156.8 | O11: 66.953085
A12: 2021 | B12: June | C12: 2133.9 | D12: 190.8 | E12: 474.7 | F12: 160.5 | G12: 159.8 | H12: 154.8 | I12: 166.3 | J12: 150.7 | K12: 154.9 | L12: 161.7 | M12: 158.8 | N12: 157.6 | O12: 71.982647
A13: 2021 | B13: July | C13: 2147 | D13: 191.2 | E13: 477.3 | F13: 161.5 | G13: 160.7 | H13: 155.8 | I13: 167 | J13: 153.1 | K13: 155.3 | L13: 163.2 | M13: 160.1 | N13: 159 | O13: 73.539061
A14: 2021 | B14: August | C14: 2142 | D14: 192.1 | E14: 483 | F14: 162.1 | G14: 162.6 | H14: 157.5 | I14: 168.4 | J14: 154 | K14: 157.6 | L14: 163.8 | M14: 160 | N14: 160 | O14: 69.804724
A15: 2021 | B15: September | C15: 2142 | D15: 192.1 | E15: 483.2 | F15: 162.1 | G15: 162.6 | H15: 157.5 | I15: 168.4 | J15: 154 | K15: 157.7 | L15: 163.7 | M15: 160 | N15: 160 | O15: 73.130738
A16: 2021 | B16: October | C16: 2175.5 | D16: 192.7 | E16: 486.3 | F16: 163.6 | G16: 164.2 | H16: 158.4 | I16: 169.1 | J16: 155.7 | K16: 158.6 | L16: 163.9 | M16: 160.8 | N16: 161 | O16: 82.107394
A17: 2021 | B17: November | C17: 2194.1 | D17: 192.9 | E17: 490.4 | F17: 164.2 | G17: 163.9 | H17: 159.3 | I17: 169.9 | J17: 154.8 | K17: 159.8 | L17: 164.3 | M17: 162.2 | N17: 161.4 | O17: 80.637301
A18: 2021 | B18: December | C18: 2180.9 | D18: 192.4 | E18: 494.2 | F18: 163.4 | G18: 164.1 | H18: 160.2 | I18: 170.6 | J18: 155.7 | K18: 160.6 | L18: 164.4 | M18: 162.6 | N18: 162 | O18: 73.298824
A19: 2022 | B19: January | C19: 2164.2 | D19: 192.2 | E19: 499.1 | F19: 164.5 | G19: 164.2 | H19: 161.1 | I19: 171.4 | J19: 156.5 | K19: 161.2 | L19: 164.7 | M19: 163 | N19: 162.7 | O19: 84.666319
... A35: 2023 | B35: May | C35: 2306.9 | D35: 201 | E35: 553.2 | F35: 175.6 | G35: 182.8 | H35: 175.2 | I35: 185.7 | J35: 164.8 | K35: 171.2 | L35: 177.1 | M35: 185.2 | N35: 175.7 | O35: 74.981548
